<?xml version="1.0" encoding="utf-8"?>
<!-- This URDF was automatically created by SolidWorks to URDF Exporter! Originally created by Stephen Brawner (brawner@gmail.com) 
     Commit Version: 1.6.0-4-g7f85cfe  Build Version: 1.6.7995.38578
     For more information, please see http://wiki.ros.org/sw_urdf_exporter -->
<robot xmlns:xacro="http://www.ros.org/wiki/xacro" name="taylor_robot_description">


  <link name="base_link"/>

  <joint name="chassis_joint" type="fixed">
    <parent link="base_link"/>
    <child link="chassis_link"/>
    <origin xyz="0 0.0 0.0"/>
  </joint>

  <link name="chassis_link">
    <inertial>
      <origin xyz="0.097174 0.025101 1.9337E-06" rpy="0 0 0"/>

      <mass value="0.65385" />

      <inertia
        ixx="0.002038"
        ixy="-4.4552E-05"
        ixz="-3.3397E-08"
        iyy="0.0059638"
        iyz="-1.9482E-08"
        izz="0.0043786"
      />

    </inertial>

    <visual>
      <origin xyz="0 0 0" rpy="0 0 0" />

      <geometry>
        <mesh>
          <uri>model://taylor_robot_description/meshes/chassis_link.STL</uri>
        </mesh>
      </geometry>

      <material name="">
        <color rgba="0.79216 0.81961 0.93333 1" />
      </material>

    </visual>

    <collision>
      <origin xyz="0 0 0" rpy="0 0 0" />
      <geometry>
        <mesh>
         <uri>model://taylor_robot_description/meshes/chassis_link.STL</uri>
        </mesh>
      </geometry>
    </collision>
  </link>

  <link name="right_wheel">
    <inertial>
      <origin
        xyz="-0.0134995209094582 -2.03221668610353E-06 -3.11022023206695E-11"
        rpy="0 0 0" />
      <mass
        value="0.0573675865850721" />
      <inertia
        ixx="2.54892095119016E-05"
        ixy="2.67586021620391E-09"
        ixz="-1.15289456121779E-14"
        iyy="1.46655937346885E-05"
        iyz="1.90020714591229E-14"
        izz="1.46625450142094E-05" />
    </inertial>
    <visual>
      <origin
        xyz="0 0 0"
        rpy="0 0 0" />
      <geometry>
        <mesh>
          <uri>model://taylor_robot_description/meshes/right_wheel.STL</uri>
        </mesh>
      </geometry>
      <material
        name="">
        <color
          rgba="0.792156862745098 0.819607843137255 0.933333333333333 1" />
      </material>
    </visual>
    <collision>
      <origin
        xyz="0 0 0"
        rpy="0 0 0" />
      <geometry>
        <mesh>
          <uri>model://taylor_robot_description/meshes/right_wheel.STL</uri>
        </mesh>
      </geometry>
    </collision>
  </link>
  <joint name="right_wheel_joint"
    type="continuous">
    <origin
      xyz="0 -0.069 0"
      rpy="1.5708 0 1.5708" />
    <parent
      link="base_link" />
    <child
      link="right_wheel" />
    <axis
      xyz="1 0 0" />
  </joint>
  <link name="left_wheel">
    <inertial>
      <origin
        xyz="0.0125004790905418 -2.03221668610353E-06 -3.11022039365138E-11"
        rpy="0 0 0" />
      <mass
        value="0.0573675865850721" />
      <inertia
        ixx="2.54892095119016E-05"
        ixy="2.67586021620392E-09"
        ixz="-1.15289456063992E-14"
        iyy="1.46655937346885E-05"
        iyz="1.90020714653885E-14"
        izz="1.46625450142094E-05" />
    </inertial>
    <visual>
      <origin
        xyz="0 0 0"
        rpy="0 0 0" />
      <geometry>
        <mesh>
         <uri>model://taylor_robot_description/meshes/left_wheel.STL</uri>
        </mesh>
      </geometry>
      <material
        name="">
        <color
          rgba="0.792156862745098 0.819607843137255 0.933333333333333 1" />
      </material>
    </visual>
    <collision>
      <origin
        xyz="0 0 0"
        rpy="0 0 0" />
      <geometry>
        <mesh>
          <uri>model://taylor_robot_description/meshes/left_wheel.STL</uri>
        </mesh>
      </geometry>
    </collision>
  </link>
  <joint name="left_wheel_joint"
    type="continuous">
    <origin
      xyz="0 0.069 0"
      rpy="1.5708 0 1.5708" />
    <parent
      link="base_link" />
    <child
      link="left_wheel" />
    <axis
      xyz="1 0 0" />
  </joint>
  <link name="caster_wheel">
    <inertial>
      <origin
        xyz="8.32667268468867E-17 -0.00982966964470464 -1.38777878078145E-17"
        rpy="0 0 0" />
      <mass
        value="0.00790078265000134" />
      <inertia
        ixx="6.3277471369579E-07"
        ixy="3.00987082068736E-22"
        ixz="-3.30872245021211E-22"
        iyy="8.42250473271864E-07"
        iyz="-4.2977660534153E-22"
        izz="5.63631984480031E-07" />
    </inertial>
    <visual>
      <origin
        xyz="0 0 0"
        rpy="0 0 0" />
      <geometry>
        <mesh>
          <uri>model://taylor_robot_description/meshes/caster_wheel.STL</uri>
        </mesh>
      </geometry>
      <material
        name="">
        <color
          rgba="0.792156862745098 0.819607843137255 0.933333333333333 1" />
      </material>
    </visual>
    <collision>
      <origin
        xyz="0 0 0"
        rpy="0 0 0" />
      <geometry>
        <mesh>
          <uri>model://taylor_robot_description/meshes/caster_wheel.STL</uri>
        </mesh>
      </geometry>
    </collision>
  </link>
  <joint name="caster_wheel_joint"
    type="continuous">
    <origin
      xyz="0.17 0 -0.009"
      rpy="1.5708 0 -0.16473" />
    <parent
      link="chassis_link" />
    <child
      link="caster_wheel" />
    <axis
      xyz="0 1 0" />
  </joint>
  <link name="lidar">
    <inertial>
      <origin
        xyz="0 0 0"
        rpy="0 0 0" />
      <mass
        value="0" />
      <inertia
        ixx="0"
        ixy="0"
        ixz="0"
        iyy="0"
        iyz="0"
        izz="0" />
    </inertial>
    <visual>
      <origin
        xyz="0 0 0"
        rpy="0 0 0" />
      <geometry>
        <mesh>
          <uri>package://taylor_robot_description/meshes/lidar.STL</uri>
        </mesh>
      </geometry>
      <material
        name="">
        <color
          rgba="1 1 1 1" />
      </material>
    </visual>
    <collision>
      <origin
        xyz="0 0 0"
        rpy="0 0 0" />
      <geometry>
        <mesh>
          <uri>package://taylor_robot_description/meshes/lidar.STL</uri>
        </mesh>
      </geometry>
    </collision>
  </link>
  <joint name="lidar_joint"
    type="fixed">
    <origin
      xyz="0.034828 0 0.0936"
      rpy="1.5708 0 0" />
    <parent
      link="chassis_link" />
    <child
      link="lidar" />
    <axis
      xyz="0 0 0" />
  </joint>
</robot>